<?xml version="1.0" encoding="UTF-8"?>
<robot xmlns:xacro="http://www.ros.org/wiki/xacro" name="planar_arm">

    <link name="base_link" />

    <joint name="joint1" type="revolute">
        <parent link="base_link" />
        <child link="link1" />
        <dynamics damping="3.0" friction="0.3" />
        <limit effort="30.0" lower="-3.1415926535" upper="3.1415926535" velocity="5.0" />
        <origin xyz="0 0 0" rpy="0 0 0" />
        <axis xyz="0 0 1" />
    </joint>

    <link name="link1">
        <collision>
            <origin rpy="0 0 0" xyz="0 0 0" />
            <geometry>
                <box size="0.1 1.0 0.01" />
            </geometry>
        </collision>
        <inertial>
            <!-- CENTER OF MASS -->
            <origin rpy="0 0 0" xyz="0.0 0.5 0.0" />
            <mass value="0.2" />
            <!-- box inertia: 1/12*m(y^2+z^2), ... -->
            <inertia ixx="0.0167" ixy="0" ixz="0" iyy="1.6833e-04" iyz="0" izz="0.0168" />
        </inertial>
    </link>

    <joint name="joint2" type="revolute">
        <parent link="link1" />
        <child link="link2" />
        <dynamics damping="3.0" friction="0.3" />
        <limit effort="30.0" lower="-3.1415926535" upper="3.1415926535" velocity="5.0" />
        <origin xyz="0.0 1.0 0.0" rpy="0 0 0" />
        <axis xyz="0 0 1" />
    </joint>

    <link name="link2">
        <collision>
            <origin rpy="0 0 0" xyz="0 0 0" />
            <geometry>
                <box size="0.1 1.0 0.01" />
            </geometry>
        </collision>
        <inertial>
            <!-- CENTER OF MASS -->
            <origin rpy="0 0 0" xyz="0.0 0.5 0.0" />
            <mass value="0.2" />
            <!-- box inertia: 1/12*m(y^2+z^2), ... -->
            <inertia ixx="0.0167" ixy="0" ixz="0" iyy="1.6833e-04" iyz="0" izz="0.0168" />
        </inertial>
    </link>

    <joint name="joint3" type="fixed">
        <parent link="link2" />
        <child link="ee" />
        <origin xyz="0.0 1.0 0.0" rpy="0 0 0" />
    </joint>

    <link name="ee" />

</robot>